
<mujoco model="env">
    <option timestep="0.005" />
    <actuator>
        <motor gear="1.0" ctrlrange="-40.0 40.0" joint="wheel0" name="motor0"/>
        <motor gear="1.0" ctrlrange="-40.0 40.0" joint="wheel1" name="motor1"/>
        <motor gear="1.0" ctrlrange="-40.0 40.0" joint="wheel2" name="motor2"/>
        <motor gear="1.0" ctrlrange="-40.0 40.0" joint="wheel3" name="motor3"/>
    </actuator>
    <worldbody>
        <body name="frame" pos="-1.0 0 0">
            <geom mass="50.0" pos="0 0 0" rgba="1 0 0 1" size="0.55 0.3 0.2" type="box"></geom>
            <joint type='free' name='frame:base' pos='0 0 0'/>
			<camera euler="0 0 0" fovy="40" name="rgb" pos="0 0 2.5"></camera>

            <body name="lf_wheel" pos="0.5 -0.4 -0.1" quat="0.7071067811865476 0.7071067811865476 0 0">
                <geom mass="1" rgba="0 0 1 1" size="0.1778 0.0125" type="cylinder"/>
                <joint axis="0 0 1" name="wheel0" type="hinge"/>                          
            </body>

            <body name="rf_wheel" pos="0.5 0.4 -0.1" quat="0.7071067811865476 0.7071067811865476 0 0">
                <geom mass="1" rgba="0 0 1 1" size="0.1778 0.05" type="cylinder"/>
                <joint axis="0 0 1" name="wheel1" type="hinge"/>
            </body>

            <body name="lb_wheel" pos="-0.5 -0.4 -0.1" quat="0.7071067811865476 0.7071067811865476 0 0">>
                <geom mass="1" rgba="0 0 1 1" size="0.1778 0.05" type="cylinder"/>
                <joint axis="0 0 1" name="wheel2" type="hinge"/>
            </body>

            <body name="rb_wheel" pos="-0.5 0.4 -0.1" quat="0.7071067811865476 0.7071067811865476 0 0">>
                <geom mass="1" rgba="0 0 1 1" size="0.1778 0.05" type="cylinder"/>
                <joint axis="0 0 1" name="wheel3" type="hinge"/>
            </body>              


        </body>

        <body name="floor" pos="0 0 -1.5">
            <geom condim="3" size="20.0 20.0 0.02" rgba="0 1 0 1" type="box"/>
            <body name="step0" pos="1.0 0 0.08636">
                <geom condim="3" size="0.14605 1.61 0.08636" rgba="1 1 1 1" type="box"/>
            </body>
            <body name="step1" pos="1.2921 0.0 0.17272">
                <geom condim="3" size="0.14605 1.61 0.17272" rgba="1 1 1 1" type="box"/>
            </body>
            <body name="step2" pos="1.5842 0.0 0.25908">
                <geom condim="3" size="0.14605 1.61 0.25908" rgba="1 1 1 1" type="box"/>
            </body>
            <body name="step3" pos="1.8763 0.0 0.34544">
                <geom condim="3" size="0.14605 1.61 0.34544" rgba="1 1 1 1" type="box"/>
            </body>
            <body name="step4" pos="2.1684 0.0 0.4318">
                <geom condim="3" size="0.14605 1.61 0.4318" rgba="1 1 1 1" type="box"/>
            </body>
            <body name="step5" pos="2.4605 0.0 0.51816">
                <geom condim="3" size="0.14605 1.61 0.51816" rgba="1 1 1 1" type="box"/>
            </body>
            <body name="step6" pos="2.7526 0.0 0.60452">
                <geom condim="3" size="0.14605 1.61 0.60452" rgba="1 1 1 1" type="box"/>
            </body>
            <body name="step7" pos="3.0447 0.0 0.69088">
                <geom condim="3" size="0.14605 1.61 0.69088" rgba="1 1 1 1" type="box"/>
            </body>
            <body name="step8" pos="3.3368 0.0 0.77724">
                <geom condim="3" size="0.14605 1.61 0.77724" rgba="1 1 1 1" type="box"/>
            </body>
            <body name="step9" pos="3.6289 0.0 0.8636">
                <geom condim="3" size="0.14605 1.61 0.8636" rgba="1 1 1 1" type="box"/>
            </body>
            <body name="step10" pos="3.921 0.0 0.94996">
                <geom condim="3" size="0.14605 1.61 0.94996" rgba="1 1 1 1" type="box"/>
                <site name='wypt0' pos="0 0 0.94996" size='0.0005 0.0005 0.0005' rgba='1 1 0 1' type='sphere'/>
            </body>

        </body>
    </worldbody>

</mujoco>