
<mujoco model="env">
    <option timestep="0.005" />
    <!-- <actuator>
        <motor gear="1.0" ctrllimited = "true" ctrlrange="-60.0 60.0" joint="wheel00" name="motor00"/>
        <motor gear="1.0" ctrllimited = "true" ctrlrange="-60.0 60.0" joint="wheel01" name="motor01"/>
        <motor gear="1.0" ctrllimited = "true" ctrlrange="-60.0 60.0" joint="wheel01" name="motor02"/>
        <motor gear="1.0" ctrllimited = "true" ctrlrange="-60.0 60.0" joint="wheel01" name="motor03"/>
        <motor gear="1.0" ctrllimited = "true" ctrlrange="-60.0 60.0" joint="wheel10" name="motor10"/>
        <motor gear="1.0" ctrllimited = "true" ctrlrange="-60.0 60.0" joint="wheel11" name="motor11"/>
        <motor gear="1.0" ctrllimited = "true" ctrlrange="-60.0 60.0" joint="wheel12" name="motor12"/>
        <motor gear="1.0" ctrllimited = "true" ctrlrange="-60.0 60.0" joint="wheel13" name="motor13"/>
        <motor gear="1.0" ctrllimited = "true" ctrlrange="-60.0 60.0" joint="wheel20" name="motor20"/>
        <motor gear="1.0" ctrllimited = "true" ctrlrange="-60.0 60.0" joint="wheel21" name="motor21"/>
        <motor gear="1.0" ctrllimited = "true" ctrlrange="-60.0 60.0" joint="wheel22" name="motor22"/>
        <motor gear="1.0" ctrllimited = "true" ctrlrange="-60.0 60.0" joint="wheel23" name="motor23"/>
        <motor gear="1.0" ctrllimited = "true" ctrlrange="-60.0 60.0" joint="wheel30" name="motor30"/>
        <motor gear="1.0" ctrllimited = "true" ctrlrange="-60.0 60.0" joint="wheel31" name="motor31"/>
        <motor gear="1.0" ctrllimited = "true" ctrlrange="-60.0 60.0" joint="wheel32" name="motor32"/>
        <motor gear="1.0" ctrllimited = "true" ctrlrange="-60.0 60.0" joint="wheel33" name="motor33"/>
    </actuator>     -->
    <actuator>
        <motor gear="1.0" ctrllimited = "false" ctrlrange="-40.0 40.0" joint="wheel00" name="motor00"/>
        <motor gear="1.0" ctrllimited = "false" ctrlrange="-40.0 40.0" joint="wheel01" name="motor01"/>
        <motor gear="1.0" ctrllimited = "false" ctrlrange="-40.0 40.0" joint="wheel01" name="motor02"/>
        <motor gear="1.0" ctrllimited = "false" ctrlrange="-40.0 40.0" joint="wheel01" name="motor03"/>
        <motor gear="1.0" ctrllimited = "false" ctrlrange="-40.0 40.0" joint="wheel10" name="motor10"/>
        <motor gear="1.0" ctrllimited = "false" ctrlrange="-40.0 40.0" joint="wheel11" name="motor11"/>
        <motor gear="1.0" ctrllimited = "false" ctrlrange="-40.0 40.0" joint="wheel12" name="motor12"/>
        <motor gear="1.0" ctrllimited = "false" ctrlrange="-40.0 40.0" joint="wheel13" name="motor13"/>
        <motor gear="1.0" ctrllimited = "false" ctrlrange="-40.0 40.0" joint="wheel20" name="motor20"/>
        <motor gear="1.0" ctrllimited = "false" ctrlrange="-40.0 40.0" joint="wheel21" name="motor21"/>
        <motor gear="1.0" ctrllimited = "false" ctrlrange="-40.0 40.0" joint="wheel22" name="motor22"/>
        <motor gear="1.0" ctrllimited = "false" ctrlrange="-40.0 40.0" joint="wheel23" name="motor23"/>
        <motor gear="1.0" ctrllimited = "false" ctrlrange="-40.0 40.0" joint="wheel30" name="motor30"/>
        <motor gear="1.0" ctrllimited = "false" ctrlrange="-40.0 40.0" joint="wheel31" name="motor31"/>
        <motor gear="1.0" ctrllimited = "false" ctrlrange="-40.0 40.0" joint="wheel32" name="motor32"/>
        <motor gear="1.0" ctrllimited = "false" ctrlrange="-40.0 40.0" joint="wheel33" name="motor33"/>
    </actuator>

    <sensor>
        <torque name='torq0' site='wheel0_t'/>
        <torque name='torq2' site='wheel2_t'/>
        <!-- <torque name='torq1' site='wheel1_t'/> -->
        <!-- <torque name='UR5e_T_sen' site='arm:force_sensor'/> -->
    </sensor>

    <worldbody>
        <body name="frame" pos="-0.5 0 -0.9" quat="1.0 0.0 0 0">
            <geom mass="75.0" pos="0 0 0" rgba="1 0 0 1" size="0.55 0.3 0.2" type="box"></geom>
            <joint type='free' name='frame:base' pos='0 0 0'/>
			<camera euler="0 0 0" fovy="40" name="rgb" pos="0 0 2.5"></camera>

            <body name="lf_wheel_asm" pos="0.5 -0.4 -0.2" quat="0.7071067811865476 0.7071067811865476 0 0">
                <geom mass="0.0001" rgba="0 0 1 0.25" size="0.0524 0.0125" type="cylinder"/>
                <joint axis="0 0 1" name="wheel00" type="hinge"/>  
                <site name="wheel0_t" pos="0 0 0.0" size='0.00005 0.00005 0.00005' rgba='0 1 0 1' type='sphere'/>
                <body name="lf_wheel_0" pos="0.1524 0.0 0.03">
                    <geom mass="1" rgba="0 0 1 1" size="0.0762 0.0125" type="cylinder"/>
                    <joint axis="0 0 1" name="wheel01" type="hinge"/>           
                </body>

                <body name="lf_wheel_1" pos="-0.0762 0.13198 0.03">
                    <geom mass="1" rgba="0 0 1 1" size="0.0762 0.0125" type="cylinder"/>
                    <joint axis="0 0 1" name="wheel02" type="hinge"/>           
                </body>   

                <body name="lf_wheel_2" pos="-0.0762 -0.13198 0.03" >
                    <geom mass="1" rgba="0 0 1 1" size="0.0762 0.0125" type="cylinder"/>
                    <joint axis="0 0 1" name="wheel03" type="hinge"/>           
                </body>                                         
            </body>

            <body name="rf_wheel_asm" pos="0.5 0.4 -0.2" quat="0.7071067811865476 0.7071067811865476 0 0">
                <geom mass="1" rgba="0 0 1 0.25" size="0.0524 0.0125" type="cylinder"/>
                <joint axis="0 0 1" name="wheel10" type="hinge"/>

                <body name="rf_wheel_0" pos="0.1524 0.0 -0.03">
                    <geom mass="1" rgba="0 0 1 1" size="0.0762 0.0125" type="cylinder"/>
                    <joint axis="0 0 1" name="wheel11" type="hinge"/>           
                </body>

                <body name="rf_wheel_1" pos="-0.0762 0.13198 -0.03">
                    <geom mass="1" rgba="0 0 1 1" size="0.0762 0.0125" type="cylinder"/>
                    <joint axis="0 0 1" name="wheel12" type="hinge"/>           
                </body>   

                <body name="rf_wheel_2" pos="-0.0762 -0.13198 -0.03" >
                    <geom mass="1" rgba="0 0 1 1" size="0.0762 0.0125" type="cylinder"/>
                    <joint axis="0 0 1" name="wheel13" type="hinge"/>           
                </body>                 
            </body>

            <body name="lb_wheel_asm" pos="-0.5 -0.4 -0.2" quat="0.7071067811865476 0.7071067811865476 0 0">>
                <geom mass="1" rgba="0 0 1 0.25" size="0.0524 0.0125" type="cylinder"/>
                <joint axis="0 0 1" name="wheel20" type="hinge"/>
                <site name="wheel2_t" pos="0 0 0.0" size='0.00005 0.00005 0.00005' rgba='0 1 0 1' type='sphere'/>
                <body name="lb_wheel_0" pos="0.1524 0.0 0.03">
                    <geom mass="1" rgba="0 0 1 1" size="0.0762 0.0125" type="cylinder"/>
                    <joint axis="0 0 1" name="wheel21" type="hinge"/>           
                </body>

                <body name="lb_wheel_1" pos="-0.0762 0.13198 0.03">
                    <geom mass="1" rgba="0 0 1 1" size="0.0762 0.0125" type="cylinder"/>
                    <joint axis="0 0 1" name="wheel22" type="hinge"/>           
                </body>   

                <body name="lb_wheel_2" pos="-0.0762 -0.13198 0.03" >
                    <geom mass="1" rgba="0 0 1 1" size="0.0762 0.0125" type="cylinder"/>
                    <joint axis="0 0 1" name="wheel23" type="hinge"/>           
                </body>  
            </body>

            <body name="rb_wheel_asm" pos="-0.5 0.4 -0.2" quat="0.7071067811865476 0.7071067811865476 0 0">>
                <geom mass="1" rgba="0 0 1 0.25" size="0.0524 0.0125" type="cylinder"/>
                <joint axis="0 0 1" name="wheel30" type="hinge"/>

                <body name="rb_wheel_0" pos="0.1524 0.0 -0.03">
                    <geom mass="1" rgba="0 0 1 1" size="0.0762 0.0125" type="cylinder"/>
                    <joint axis="0 0 1" name="wheel31" type="hinge"/>           
                </body>

                <body name="rb_wheel_1" pos="-0.0762 0.13198 -0.03">
                    <geom mass="1" rgba="0 0 1 1" size="0.0762 0.0125" type="cylinder"/>
                    <joint axis="0 0 1" name="wheel32" type="hinge"/>           
                </body>   

                <body name="rb_wheel_2" pos="-0.0762 -0.13198 -0.03" >
                    <geom mass="1" rgba="0 0 1 1" size="0.0762 0.0125" type="cylinder"/>
                    <joint axis="0 0 1" name="wheel33" type="hinge"/>           
                </body>                  
            </body>              
        </body>

        <body name="floor" pos="0 0 -1.5">
            <geom condim="3" size="20.0 20.0 0.02" rgba="0 1 0 1" type="box"/>
            <body name="step0" pos="1.0 0 0.08636">
                <geom condim="3" size="0.14605 1.61 0.08636" rgba="1 1 1 1" type="box"/>
            </body>
            <body name="step1" pos="1.2921 0.0 0.17272">
                <geom condim="3" size="0.14605 1.61 0.17272" rgba="1 1 1 1" type="box"/>
            </body>
            <body name="step2" pos="1.5842 0.0 0.25908">
                <geom condim="3" size="0.14605 1.61 0.25908" rgba="1 1 1 1" type="box"/>
            </body>
            <body name="step3" pos="1.8763 0.0 0.34544">
                <geom condim="3" size="0.14605 1.61 0.34544" rgba="1 1 1 1" type="box"/>
            </body>
            <body name="step4" pos="2.1684 0.0 0.4318">
                <geom condim="3" size="0.14605 1.61 0.4318" rgba="1 1 1 1" type="box"/>
            </body>
            <body name="step5" pos="2.4605 0.0 0.51816">
                <geom condim="3" size="0.14605 1.61 0.51816" rgba="1 1 1 1" type="box"/>
            </body>
            <body name="step6" pos="2.7526 0.0 0.60452">
                <geom condim="3" size="0.14605 1.61 0.60452" rgba="1 1 1 1" type="box"/>
            </body>
            <body name="step7" pos="3.0447 0.0 0.69088">
                <geom condim="3" size="0.14605 1.61 0.69088" rgba="1 1 1 1" type="box"/>
            </body>
            <body name="step8" pos="3.3368 0.0 0.77724">
                <geom condim="3" size="0.14605 1.61 0.77724" rgba="1 1 1 1" type="box"/>
            </body>
            <body name="step9" pos="3.6289 0.0 0.8636">
                <geom condim="3" size="0.14605 1.61 0.8636" rgba="1 1 1 1" type="box"/>
            </body>
            <body name="step10" pos="5.921 0.0 0.94996">
                <geom condim="3" size="2.14605 1.61 0.94996" rgba="1 1 1 1" type="box"/>
                <site name='wypt0' pos="0 0 0.94996" size='0.0005 0.0005 0.0005' rgba='1 1 0 1' type='sphere'/>
            </body>

        </body>
    </worldbody>

</mujoco>